Workbook

Sheet Scraped data 
A1: Company Name | B1: Date | C1: Instruments | D1: Size | E1: Current Ratings | F1: Outlook | G1: Rating Rationale PDF | H1: Source URL
A2: Air Perfection | B2: July 18, 2025 | C2: Long Term Bank Facility | D2: Rs. 9.00 Cr. | E2: IVR C (INC)(Downgraded) | F2: Negative | G2: https://infomericstorage.blob.core.windows.net/uploads/pr_Air_Perfection_18july25_138dc0658d.pdf | H2: https://www.infomerics.com/pressrelease/air-perfection
A3: Air Perfection | B3: July 18, 2025 | C3: Short Term Facility | D3: Rs. 10.00 Cr. | E3: IVR A4 (INC)(Reaffirmed) | F3: Nil | G3: https://infomericstorage.blob.core.windows.net/uploads/pr_Air_Perfection_18july25_138dc0658d.pdf | H3: https://www.infomerics.com/pressrelease/air-perfection
A4: Uniproducts India Limited | B4: January 25, 2021 | C4: Long Term Bank Facilities | D4: Rs. 180.00 Cr. | E4: IVR BB (Revised and withdrawn) | F4: Stable | G4: https://infomericstorage.blob.core.windows.net/uploads/pr_uniproducts_india_ltd_jan25_2021_f888300be0.pdf | H4: https://www.infomerics.com/pressrelease/uniproducts-india-limited
A5: Uniproducts India Limited | B5: January 25, 2021 | C5: Short Term Bank Facilities | D5: Rs. 20.00 Cr. | E5: IVR A4 (Revised and withdrawn) | F5: Nil | G5: https://infomericstorage.blob.core.windows.net/uploads/pr_uniproducts_india_ltd_jan25_2021_f888300be0.pdf | H5: https://www.infomerics.com/pressrelease/uniproducts-india-limited
A6: Mitsumi Housing Private Limited | B6: October 28, 2021 | C6: Long Term Fund Based Facility - Cash Credit (Proposed) | D6: NIL | E6: Withdrawn | F6: Nil | G6: https://infomericstorage.blob.core.windows.net/uploads/pr_mitsumi_housing_oct28_2021_bc1db02e68.pdf | H6: https://www.infomerics.com/pressrelease/mitsumi-housing-private-limited
A7: Mitsumi Housing Private Limited | B7: October 28, 2021 | C7: Short Term Non-Fund Based Facility - Bank Guarantee (Proposed) | D7: NIL | E7: Withdrawn | F7: Nil | G7: https://infomericstorage.blob.core.windows.net/uploads/pr_mitsumi_housing_oct28_2021_bc1db02e68.pdf | H7: https://www.infomerics.com/pressrelease/mitsumi-housing-private-limited
A8: Grand Canyon SEZ Private Limited | B8: October 14, 2025 | C8: Long Term Bank Facilities - LRD | D8: Rs. 283.03 Cr. | E8: IVR BB (INC)(Downgraded) | F8: Negative | G8: https://infomericstorage.blob.core.windows.net/uploads/pr_grand_canyonsez_14oct25_d2c647af6c.pdf | H8: https://www.infomerics.com/pressrelease/grand-canyon-sez-private-limited
A9: Nayati Medical Private Limited (Formerly known as Nayati Pharma Private Limited) | B9: February 17, 2025 | C9: Long Term Bank Facilities | D9: Rs. 10.00 Cr. | E9: IVR C- (INC)(Downgraded) | F9: Negative | G9: https://infomericstorage.blob.core.windows.net/uploads/pr_nayati_medical_17feb25_0f07ecf4d0.pdf | H9: https://www.infomerics.com/pressrelease/nayati-medical-private-limited-(formerly-known-as-nayati-pharma-private-limited)
A10: Suraksha Asset Reconstruction Private Limited (SARPL) | B10: October 12, 2019 | C10: Commercial Paper | D10: Rs. 600.00 Cr. | E10: IVR A1+ (CE) (Withdrawn) | F10: Nil | G10: # | H10: https://www.infomerics.com/pressrelease/suraksha-asset-reconstruction-private-limited-(sarpl)
A11: Unimed Technologies Limited | B11: October 12, 2019 | C11: Commercial Paper | D11: Rs. 500.00 Cr. | E11: IVR A1+ (CE) (Withdrawn) | F11: Nil | G11: https://infomericstorage.blob.core.windows.net/uploads/PR_UTL_Withdrawal_12_10_2019_a52bef172c.pdf | H11: https://www.infomerics.com/pressrelease/unimed-technologies-limited
A12: MJ Pharmaceuticals Private Limited | B12: October 12, 2019 | C12: Commercial Paper | D12: Rs. 750.00 Cr. | E12: IVR A1+ (CE) (Withdrawn) | F12: Nil | G12: https://infomericstorage.blob.core.windows.net/uploads/PR_MJ_Pharmaceuticals_12_10_2019_976b1b62f0.pdf | H12: https://www.infomerics.com/pressrelease/mj-pharmaceuticals-private-limited
... A52: Achiievers Finance India Limited | B52: October 6, 2025 | C52: Proposed Non-Convertible Debentures | D52: Rs. 35.37 Cr. (Increased from Rs. 9.45 Cr.) | E52: IVR BBB- (Upgraded) | F52: Stable | G52: https://infomericstorage.blob.core.windows.net/uploads/pr_achiievers_finance_6oct25_daf21f7389.pdf | H52: https://www.infomerics.com/pressrelease/achiievers-finance-india-limited
A53: Achiievers Finance India Limited | B53: October 6, 2025 | C53: Non-Convertible Debentures | D53: 0 | E53: Withdrawn | F53: Nil | G53: https://infomericstorage.blob.core.windows.net/uploads/pr_achiievers_finance_6oct25_daf21f7389.pdf | H53: https://www.infomerics.com/pressrelease/achiievers-finance-india-limited
A54: Simplex Infrastructures Limited | B54: September 24, 2025 | C54: Long Term Bank Facilities | D54: Rs. 2600.00 Cr. | E54: IVR D (INC)(Reaffirmed) | F54: Nil | G54: https://infomericstorage.blob.core.windows.net/uploads/pr_simplex_infra_24sep25_6ac9ced126.pdf | H54: https://www.infomerics.com/pressrelease/simplex-infrastructures-limited
A55: Simplex Infrastructures Limited | B55: September 24, 2025 | C55: Short Term Bank Facilities | D55: Rs. 75.00 Cr. | E55: IVR D (INC)(Reaffirmed) | F55: Nil | G55: https://infomericstorage.blob.core.windows.net/uploads/pr_simplex_infra_24sep25_6ac9ced126.pdf | H55: https://www.infomerics.com/pressrelease/simplex-infrastructures-limited
A56: Nidhi Textiles | B56: December 11, 2018 | C56: Long Term Fund Based Limits | D56: Rs. 9.00 cr. | E56: IVR BB- (Reaffirmed and Withdrawn) | F56: Stable | G56: https://infomericstorage.blob.core.windows.net/uploads/Press_Release_Nidhi_withdrawal_077eac4a81.pdf | H56: https://www.infomerics.com/pressrelease/nidhi-textiles
A57: Nidhi Textiles | B57: December 11, 2018 | C57: Working Capital Demand Loan | D57: Rs.2.50 Cr. | E57: IVR BB- (Reaffirmed and Withdrawn) | F57: Stable | G57: https://infomericstorage.blob.core.windows.net/uploads/Press_Release_Nidhi_withdrawal_077eac4a81.pdf | H57: https://www.infomerics.com/pressrelease/nidhi-textiles
A58: Gemini Fashion | B58: December 11, 2018 | C58: Long Term Fund Based Limits | D58: Rs. 6.00 cr. | E58: IVR BB- (Reaffirmed and Withdrawn) | F58: Stable | G58: https://infomericstorage.blob.core.windows.net/uploads/Press_Release_Gemini_Withdrawal_f9d45f3bcb.pdf | H58: https://www.infomerics.com/pressrelease/gemini-fashion
A59: Gemini Fashion | B59: December 11, 2018 | C59: Working Capital Demand Loan | D59: Rs.2.50 Cr. | E59: IVR BB- (Reaffirmed and Withdrawn) | F59: Stable | G59: https://infomericstorage.blob.core.windows.net/uploads/Press_Release_Gemini_Withdrawal_f9d45f3bcb.pdf | H59: https://www.infomerics.com/pressrelease/gemini-fashion
A60: Shriniwas Spintex Industries Private Limited | B60: December 29, 2025 | C60: Long Term Fund Based Bank Facilities | D60: Rs. 33.03 Cr. | E60: IVR BB (INC)(Downgraded) | F60: Negative | G60: https://infomericstorage.blob.core.windows.net/uploads/pr_SSIPL_29dec25_2e2982e02d.pdf | H60: https://www.infomerics.com/pressrelease/shriniwas-spintex-industries-private-limited
A61: Shriniwas Spintex Industries Private Limited | B61: December 29, 2025 | C61: Short Term Non-Fund Based Bank Facilities | D61: Rs. 1.90 Cr. | E61: IVR A4 (ISSUER NOT COOPERATING) | F61: Nil | G61: https://infomericstorage.blob.core.windows.net/uploads/pr_SSIPL_29dec25_2e2982e02d.pdf | H61: https://www.infomerics.com/pressrelease/shriniwas-spintex-industries-private-limited
A62: Velan Kraft House Private Limited | B62: July 17, 2025 | C62: Long Term Bank Facilities | D62: Rs. 43.00 Cr. | E62: IVR D (INC)(Reaffirmed) | F62: Nil | G62: https://infomericstorage.blob.core.windows.net/uploads/pr_velankraft_17july25_7587ffe110.pdf | H62: https://www.infomerics.com/pressrelease/velan-kraft-house-private-limited
A63: Anvil Energy Private Limited (erstwhile Anvil Cables Private Limited) | B63: January 27, 2026 | C63: Long Term Bank Facilities | D63: Rs. 147.30 Cr. (enhanced from Rs. 90.47 Cr. and includes proposed facility of Rs. 16.00 Cr.) | E63: IVR BBB+ (Reaffirmed) | F63: Stable | G63: https://infomericstorage.blob.core.windows.net/uploads/pr_Anvil_Energy_27jan26_718f2983a4.pdf | H63: https://www.infomerics.com/pressrelease/anvil-energy-private-limited-erstwhile-anvil-cables-private-limited
A64: Anvil Energy Private Limited (erstwhile Anvil Cables Private Limited) | B64: January 27, 2026 | C64: Short Term Bank Facilities | D64: Rs. 215.50 Cr. (enhanced from Rs. 109.33 Cr. and includes proposed facility of Rs. 31.32 Cr.) | E64: IVR A2 (Reaffirmed) | F64: Nil | G64: https://infomericstorage.blob.core.windows.net/uploads/pr_Anvil_Energy_27jan26_718f2983a4.pdf | H64: https://www.infomerics.com/pressrelease/anvil-energy-private-limited-erstwhile-anvil-cables-private-limited
A65: YSR Spinning and Weaving Mills Private Limited | B65: March 24, 2021 | C65: Long Term Bank Facilities | D65: Rs. 20.20 Cr. | E65: IVR BB (Withdrawn) | F65: Stable | G65: https://infomericstorage.blob.core.windows.net/uploads/pr_ysr_spinning_weaving_mar24_2021_06df102372.pdf | H65: https://www.infomerics.com/pressrelease/ysr-spinning-and-weaving-mills-private-limited
... A74: Usha Financial Services Limited | B74: December 5, 2025 | C74: Proposed Long Term Fund Based Bank Facilities - Term Loan | D74: Rs. 66.37 Cr. | E74: IVR BBB- (Downgraded) | F74: Stable | G74: https://infomericstorage.blob.core.windows.net/uploads/PR_Usha_Financial_Services05_Dec25_768202b3d1.pdf | H74: https://www.infomerics.com/pressrelease/usha-financial-services-limited
A75: Usha Financial Services Limited | B75: December 5, 2025 | C75: Long Term Fund Based Bank Facilities - Term Loan | D75: 0 | E75: Withdrawn | F75: Nil | G75: https://infomericstorage.blob.core.windows.net/uploads/PR_Usha_Financial_Services05_Dec25_768202b3d1.pdf | H75: https://www.infomerics.com/pressrelease/usha-financial-services-limited
A76: Rean Watertech Private Limited | B76: July 31, 2025 | C76: Long Term Facilities | D76: Rs. 46.15 Cr. | E76: IVR BBB (Upgraded) (Withdrawn) | F76: Stable | G76: https://infomericstorage.blob.core.windows.net/uploads/Pr_Rean_Watertech_31july25_fc7e889103.pdf | H76: https://www.infomerics.com/pressrelease/rean-watertech-private-limited
A77: Rean Watertech Private Limited | B77: July 31, 2025 | C77: Long Term / Short Term Facilities | D77: Rs. 5.85 Cr. | E77: IVR BBB/ IVR A3+ (Upgraded)(Withdrawn) | F77: Stable/- | G77: https://infomericstorage.blob.core.windows.net/uploads/Pr_Rean_Watertech_31july25_fc7e889103.pdf | H77: https://www.infomerics.com/pressrelease/rean-watertech-private-limited
A78: Aavanti Renewable Energy Private Limited | B78: October 9, 2024 | C78: Long Term Bank Facilities | D78: Rs. 0.00 Cr. | E78: Withdrawn | F78: Nil | G78: https://infomericstorage.blob.core.windows.net/uploads/Pr_Aavanti_Renewable_Energy_9oct24_262d912977.pdf | H78: https://www.infomerics.com/pressrelease/aavanti-renewable-energy-private-limited
A79: Kanak Instalments Limited | B79: August 8, 2025 | C79: Long Term Fund Based Limits (Proposed) | D79: Rs. 5.00 Cr. | E79: IVR B- (INC)(Reaffirmed) | F79: Negative | G79: https://infomericstorage.blob.core.windows.net/uploads/pr_kanak_instalments_8aug25_aa9e787a12.pdf | H79: https://www.infomerics.com/pressrelease/kanak-instalments-limited
A80: MEP Longjian VTR Private Limited | B80: October 29, 2025 | C80: Long Term Bank Facilities - Proposed | D80: Rs. 646.93 Cr. | E80: IVR C- (INC)(Downgraded) | F80: Negative | G80: https://infomericstorage.blob.core.windows.net/uploads/pr_MEP_Longjian_VTR_29oct25_a9cf596c84.pdf | H80: https://www.infomerics.com/pressrelease/mep-longjian-vtr-private-limited
A81: AP Securitas Private Limited | B81: November 9, 2022 | C81: Long Term Bank Facilities - Cash Credit | D81: Rs. 34.00 Cr. | E81: IVR BBB (Reaffirmed and withdrawn) | F81: Stable | G81: https://infomericstorage.blob.core.windows.net/uploads/pr_AP_Securitas_9nov22_1bd69a386e.pdf | H81: https://www.infomerics.com/pressrelease/ap-securitas-private-limited
A82: AP Securitas Private Limited | B82: November 9, 2022 | C82: Short Term Bank Facilities - Sales Invoice Discounting | D82: Rs. 15.00 Cr. | E82: IVR A3+ (Reaffirmed and withdrawn) | F82: Nil | G82: https://infomericstorage.blob.core.windows.net/uploads/pr_AP_Securitas_9nov22_1bd69a386e.pdf | H82: https://www.infomerics.com/pressrelease/ap-securitas-private-limited
A83: AP Securitas Private Limited | B83: November 9, 2022 | C83: Short Term Bank Facilities - Bank Guarantee | D83: Rs. 15.00 Cr. | E83: IVR A3+ (Reaffirmed and withdrawn) | F83: Nil | G83: https://infomericstorage.blob.core.windows.net/uploads/pr_AP_Securitas_9nov22_1bd69a386e.pdf | H83: https://www.infomerics.com/pressrelease/ap-securitas-private-limited
A84: JPM Exports Private Limited | B84: June 19, 2025 | C84: Long Term Bank Facilities | D84: Rs. 50.00 Cr. | E84: IVR D (INC)(Reaffirmed) | F84: Nil | G84: https://infomericstorage.blob.core.windows.net/uploads/pr_JPM_Exports_19june25_cdd6900534.pdf | H84: https://www.infomerics.com/pressrelease/jpm-exports-private-limited
A85: Mahadev Yarns Private Limited | B85: December 29, 2021 | C85: Long Term Fund Based Facilities - Term Loan | D85: Rs. 4.14 Cr. | E85: IVR B (INC)(Reaffirmed and Withdrawn) | F85: Nil | G85: https://infomericstorage.blob.core.windows.net/uploads/pr_Mahadev_Yarns_29dec21_53e5656ffb.pdf | H85: https://www.infomerics.com/pressrelease/mahadev-yarns-private-limited
A86: Mahadev Yarns Private Limited | B86: December 29, 2021 | C86: Long Term Bank Facilities - Cash Credit | D86: Rs. 11.36 Cr. (including proposed limit of Rs. 0.36 crore) | E86: IVR B (INC)(Reaffirmed and Withdrawn) | F86: Nil | G86: https://infomericstorage.blob.core.windows.net/uploads/pr_Mahadev_Yarns_29dec21_53e5656ffb.pdf | H86: https://www.infomerics.com/pressrelease/mahadev-yarns-private-limited
A87: Mahadev Yarns Private Limited | B87: December 29, 2021 | C87: Short Term Bank Facilities - Bank Guarantee | D87: Rs. 0.50 Cr. | E87: IVR A4 (INC)(Reaffirmed and Withdrawn) | F87: Nil | G87: https://infomericstorage.blob.core.windows.net/uploads/pr_Mahadev_Yarns_29dec21_53e5656ffb.pdf | H87: https://www.infomerics.com/pressrelease/mahadev-yarns-private-limited
...

Sheet Server
A1: id | B1: documentId | C1: CompanyName | D1: PAN | E1: PANData | F1: isActive | G1: createdAt | H1: updatedAt | I1: publishedAt | J1: dummy | K1: slug | L1: final link | M1: Address | N1: Date | O1: SubTitle | P1: industry | Q1: id | R1: documentId | S1: IndustryTitle | T1: isActive | U1: createdAt | V1: updatedAt | W1: publishedAt | X1: meta
A2: 4481 | B2: h702i4gdaz9m5rdgzjt5h6ws | C2: Air Perfection | D2: =VLOOKUP(C2,'Scraped data '!A:A,1,0) -> Air Perfection | F2: true | G2: 2013-03-20T18:30:00.000Z | H2: 2025-11-07T10:42:37.675Z | I2: 2025-11-07T10:42:37.587Z | J2: https://www.infomerics.com/pressrelease/ | K2: air-perfection | L2: =J2&M2 -> https://www.infomerics.com/pressrelease/ | Q2: 2 | R2: yg0r8xoabi2nh72hqsuefyv6 | S2: Other | T2: true | U2: 2025-04-01T06:06:11.255Z | V2: 2025-04-01T06:06:11.255Z | W2: 2025-04-01T06:06:11.251Z
A3: 4482 | B3: yf552pthwveqfbtj98an88bc | C3: Uniproducts India Limited | D3: =VLOOKUP(C3,'Scraped data '!A:A,1,0) -> Uniproducts India Limited | F3: true | G3: 2013-03-20T18:30:00.000Z | H3: 2025-11-07T10:42:38.552Z | I3: 2025-11-07T10:42:38.520Z | J3: https://www.infomerics.com/pressrelease/ | K3: uniproducts-india-limited | Q3: 2 | R3: yg0r8xoabi2nh72hqsuefyv6 | S3: Other | T3: true | U3: 2025-04-01T06:06:11.255Z | V3: 2025-04-01T06:06:11.255Z | W3: 2025-04-01T06:06:11.251Z
A4: 4483 | B4: vq1mdxcr1ucxsy6wtsyehmhl | C4: Mitsumi Housing Private Limited | D4: =VLOOKUP(C4,'Scraped data '!A:A,1,0) -> Mitsumi Housing Private Limited | F4: true | G4: 2013-03-20T18:30:00.000Z | H4: 2025-11-07T10:42:39.384Z | I4: 2025-11-07T10:42:39.350Z | J4: https://www.infomerics.com/pressrelease/ | K4: mitsumi-housing-private-limited | Q4: 2 | R4: yg0r8xoabi2nh72hqsuefyv6 | S4: Other | T4: true | U4: 2025-04-01T06:06:11.255Z | V4: 2025-04-01T06:06:11.255Z | W4: 2025-04-01T06:06:11.251Z
A5: 4484 | B5: khscysv5z044po2ebdpqvmep | C5: Grand Canyon SEZ Private Limited | D5: =VLOOKUP(C5,'Scraped data '!A:A,1,0) -> Grand Canyon SEZ Private Limited | F5: true | G5: 2013-03-20T18:30:00.000Z | H5: 2025-11-07T10:42:42.645Z | I5: 2025-11-07T10:42:42.563Z | J5: https://www.infomerics.com/pressrelease/ | K5: grand-canyon-sez-private-limited | Q5: 2 | R5: yg0r8xoabi2nh72hqsuefyv6 | S5: Other | T5: true | U5: 2025-04-01T06:06:11.255Z | V5: 2025-04-01T06:06:11.255Z | W5: 2025-04-01T06:06:11.251Z
A6: 4485 | B6: z2jr5teujbcixtp9jpmq9gjs | C6: Nayati Medical Private Limited (Formerly known as Nayati Pharma Private Limited) | D6: =VLOOKUP(C6,'Scraped data '!A:A,1,0) -> Nayati Medical Private Limited (Formerly known as Nayati Pharma Private Limited) | F6: true | G6: 2014-03-20T18:30:00.000Z | H6: 2025-11-07T10:42:45.964Z | I6: 2025-11-07T10:42:45.877Z | J6: https://www.infomerics.com/pressrelease/ | K6: nayati-medical-private-limited-(formerly-known-as-nayati-pharma-private-limited) | Q6: 2 | R6: yg0r8xoabi2nh72hqsuefyv6 | S6: Other | T6: true | U6: 2025-04-01T06:06:11.255Z | V6: 2025-04-01T06:06:11.255Z | W6: 2025-04-01T06:06:11.251Z
A7: 4486 | B7: fnrzkvsgdt5psiinavmekfsd | C7: Suraksha Asset Reconstruction Private Limited (SARPL) | D7: =VLOOKUP(C7,'Scraped data '!A:A,1,0) -> Suraksha Asset Reconstruction Private Limited (SARPL) | F7: true | G7: 2014-03-20T18:30:00.000Z | H7: 2025-11-07T10:42:47.416Z | I7: 2025-11-07T10:42:47.366Z | J7: https://www.infomerics.com/pressrelease/ | K7: suraksha-asset-reconstruction-private-limited-(sarpl) | Q7: 2 | R7: yg0r8xoabi2nh72hqsuefyv6 | S7: Other | T7: true | U7: 2025-04-01T06:06:11.255Z | V7: 2025-04-01T06:06:11.255Z | W7: 2025-04-01T06:06:11.251Z
A8: 4487 | B8: jf5hici3wiauhf3c622lj8j9 | C8: Unimed Technologies Limited | D8: =VLOOKUP(C8,'Scraped data '!A:A,1,0) -> Unimed Technologies Limited | F8: true | G8: 2015-03-20T18:30:00.000Z | H8: 2025-11-07T10:42:48.641Z | I8: 2025-11-07T10:42:48.605Z | J8: https://www.infomerics.com/pressrelease/ | K8: unimed-technologies-limited | Q8: 2 | R8: yg0r8xoabi2nh72hqsuefyv6 | S8: Other | T8: true | U8: 2025-04-01T06:06:11.255Z | V8: 2025-04-01T06:06:11.255Z | W8: 2025-04-01T06:06:11.251Z
A9: 4488 | B9: llx26z5m2dz84hoajqbi6ghn | C9: MJ Pharmaceuticals Private Limited | D9: =VLOOKUP(C9,'Scraped data '!A:A,1,0) -> MJ Pharmaceuticals Private Limited | F9: true | G9: 2015-03-20T18:30:00.000Z | H9: 2025-11-07T10:42:49.804Z | I9: 2025-11-07T10:42:49.768Z | J9: https://www.infomerics.com/pressrelease/ | K9: mj-pharmaceuticals-private-limited | Q9: 2 | R9: yg0r8xoabi2nh72hqsuefyv6 | S9: Other | T9: true | U9: 2025-04-01T06:06:11.255Z | V9: 2025-04-01T06:06:11.255Z | W9: 2025-04-01T06:06:11.251Z
A10: 4489 | B10: mkiemvu9tb72h37c90z4hqr2 | C10: Aditya Medisales Limited | D10: =VLOOKUP(C10,'Scraped data '!A:A,1,0) -> Aditya Medisales Limited | F10: true | G10: 2015-03-20T18:30:00.000Z | H10: 2025-11-07T10:42:50.615Z | I10: 2025-11-07T10:42:50.588Z | J10: https://www.infomerics.com/pressrelease/ | K10: aditya-medisales-limited | Q10: 2 | R10: yg0r8xoabi2nh72hqsuefyv6 | S10: Other | T10: true | U10: 2025-04-01T06:06:11.255Z | V10: 2025-04-01T06:06:11.255Z | W10: 2025-04-01T06:06:11.251Z
A11: 4490 | B11: cr5x1da9hh1xmpst7gia9x2l | C11: Royal Realtors | D11: =VLOOKUP(C11,'Scraped data '!A:A,1,0) -> Royal Realtors | F11: true | G11: 2015-03-20T18:30:00.000Z | H11: 2025-11-07T10:42:51.538Z | I11: 2025-11-07T10:42:51.511Z | J11: https://www.infomerics.com/pressrelease/ | K11: royal-realtors | Q11: 2 | R11: yg0r8xoabi2nh72hqsuefyv6 | S11: Other | T11: true | U11: 2025-04-01T06:06:11.255Z | V11: 2025-04-01T06:06:11.255Z | W11: 2025-04-01T06:06:11.251Z
A12: 4491 | B12: g0qhpi9ygvcqsprm3sn035z8 | C12: India Mega Agro Anaj Limited | D12: =VLOOKUP(C12,'Scraped data '!A:A,1,0) -> India Mega Agro Anaj Limited | F12: true | G12: 2016-03-20T18:30:00.000Z | H12: 2025-12-01T13:44:33.631Z | I12: 2025-12-01T13:44:33.330Z | J12: https://www.infomerics.com/pressrelease/ | K12: india-mega-agro-anaj-limited | Q12: 2 | R12: yg0r8xoabi2nh72hqsuefyv6 | S12: Other | T12: true | U12: 2025-04-01T06:06:11.255Z | V12: 2025-04-01T06:06:11.255Z | W12: 2025-04-01T06:06:11.251Z
A13: 4492 | B13: lznynmfhw44i1y3cflhwjugd | C13: Yadu Sugar Limited | D13: =VLOOKUP(C13,'Scraped data '!A:A,1,0) -> Yadu Sugar Limited | F13: true | G13: 2016-03-20T18:30:00.000Z | H13: 2025-12-18T05:34:31.845Z | I13: 2025-12-18T05:34:31.529Z | J13: https://www.infomerics.com/pressrelease/ | K13: yadu-sugar-limited | Q13: 2 | R13: yg0r8xoabi2nh72hqsuefyv6 | S13: Other | T13: true | U13: 2025-04-01T06:06:11.255Z | V13: 2025-04-01T06:06:11.255Z | W13: 2025-04-01T06:06:11.251Z
A14: 4493 | B14: rzc8eoeebcn9twcdafed52us | C14: Shah Nanji Nagsi Export Private Limited | D14: =VLOOKUP(C14,'Scraped data '!A:A,1,0) -> Shah Nanji Nagsi Export Private Limited | F14: true | G14: 2016-03-20T18:30:00.000Z | H14: 2025-11-07T10:43:00.567Z | I14: 2025-11-07T10:43:00.497Z | J14: https://www.infomerics.com/pressrelease/ | K14: shah-nanji-nagsi-export-private-limited | Q14: 2 | R14: yg0r8xoabi2nh72hqsuefyv6 | S14: Other | T14: true | U14: 2025-04-01T06:06:11.255Z | V14: 2025-04-01T06:06:11.255Z | W14: 2025-04-01T06:06:11.251Z
... A880: 5359 | B880: dbnrhl4ee61s7vny50pb8zlx | C880: Viraj Profiles Private Limited (Erstwhile Viraj Profiles Limited) | D880: =VLOOKUP(C880,'Scraped data '!A:A,1,0) -> Viraj Profiles Private Limited (Erstwhile Viraj Profiles Limited) | F880: true | G880: 2005-11-20T18:30:00.000Z | H880: 2025-11-07T11:26:54.008Z | I880: 2025-11-07T11:26:53.888Z | J880: https://www.infomerics.com/pressrelease/ | K880: viraj-profiles-private-limited-erstwhile-viraj-profiles-limited | Q880: 2 | R880: yg0r8xoabi2nh72hqsuefyv6 | S880: Other | T880: true | U880: 2025-04-01T06:06:11.255Z | V880: 2025-04-01T06:06:11.255Z | W880: 2025-04-01T06:06:11.251Z
A881: 5360 | B881: a493jwp6xec54vc0x8p2y4ll | C881: K&R Rail Engineering Limited | D881: =VLOOKUP(C881,'Scraped data '!A:A,1,0) -> K&R Rail Engineering Limited | F881: true | G881: 2005-11-20T18:30:00.000Z | H881: 2025-11-20T10:11:17.743Z | I881: 2025-11-20T10:11:17.447Z | J881: https://www.infomerics.com/pressrelease/ | K881: kr-rail-engineering-limited
A882: 5361 | B882: w6ly8l8qsrmhm758jhpu3yup | C882: Optiemus Infracom Limited | D882: =VLOOKUP(C882,'Scraped data '!A:A,1,0) -> Optiemus Infracom Limited | F882: true | G882: 2005-11-20T18:30:00.000Z | H882: 2025-11-07T11:26:58.082Z | I882: 2025-11-07T11:26:58.047Z | J882: https://www.infomerics.com/pressrelease/ | K882: optiemus-infracom-limited | Q882: 2 | R882: yg0r8xoabi2nh72hqsuefyv6 | S882: Other | T882: true | U882: 2025-04-01T06:06:11.255Z | V882: 2025-04-01T06:06:11.255Z | W882: 2025-04-01T06:06:11.251Z
A883: 5362 | B883: vwhbfnkz3wpqve40mfdr7ax0 | C883: Amar Shakti Commerce & Industries Limited | D883: =VLOOKUP(C883,'Scraped data '!A:A,1,0) -> Amar Shakti Commerce & Industries Limited | F883: true | G883: 2006-11-20T18:30:00.000Z | H883: 2025-11-25T12:09:53.430Z | I883: 2025-11-25T12:09:53.266Z | J883: https://www.infomerics.com/pressrelease/ | K883: amar-shakti-commerce--industries-limited | Q883: 2 | R883: yg0r8xoabi2nh72hqsuefyv6 | S883: Other | T883: true | U883: 2025-04-01T06:06:11.255Z | V883: 2025-04-01T06:06:11.255Z | W883: 2025-04-01T06:06:11.251Z
A884: 5363 | B884: xgiyt3wu5gf2m6gwa3y5i2ua | C884: Spray Engineering Devices Limited | D884: =VLOOKUP(C884,'Scraped data '!A:A,1,0) -> Spray Engineering Devices Limited | F884: true | G884: 2006-11-20T18:30:00.000Z | H884: 2025-11-07T11:27:04.243Z | I884: 2025-11-07T11:27:04.148Z | J884: https://www.infomerics.com/pressrelease/ | K884: spray-engineering-devices-limited | Q884: 2 | R884: yg0r8xoabi2nh72hqsuefyv6 | S884: Other | T884: true | U884: 2025-04-01T06:06:11.255Z | V884: 2025-04-01T06:06:11.255Z | W884: 2025-04-01T06:06:11.251Z
A885: 5364 | B885: kvkrtzcq2jietztgyug89fmi | C885: Mono Steel India Limited | D885: =VLOOKUP(C885,'Scraped data '!A:A,1,0) -> Mono Steel India Limited | F885: true | G885: 2006-11-20T18:30:00.000Z | H885: 2025-11-07T11:27:07.598Z | I885: 2025-11-07T11:27:07.524Z | J885: https://www.infomerics.com/pressrelease/ | K885: mono-steel-india-limited | Q885: 2 | R885: yg0r8xoabi2nh72hqsuefyv6 | S885: Other | T885: true | U885: 2025-04-01T06:06:11.255Z | V885: 2025-04-01T06:06:11.255Z | W885: 2025-04-01T06:06:11.251Z
A886: 5365 | B886: s7spm8flqm8o189bnzb7ujob | C886: BFG International Private Limited | D886: =VLOOKUP(C886,'Scraped data '!A:A,1,0) -> BFG International Private Limited | F886: true | G886: 2006-11-20T18:30:00.000Z | H886: 2025-11-07T11:27:10.482Z | I886: 2025-11-07T11:27:10.388Z | J886: https://www.infomerics.com/pressrelease/ | K886: bfg-international-private-limited | Q886: 2 | R886: yg0r8xoabi2nh72hqsuefyv6 | S886: Other | T886: true | U886: 2025-04-01T06:06:11.255Z | V886: 2025-04-01T06:06:11.255Z | W886: 2025-04-01T06:06:11.251Z
A887: 5366 | B887: khxzkjtxfp8fiw9uw5pzntgj | C887: Lifeline Multi Ventures Private Limited | D887: =VLOOKUP(C887,'Scraped data '!A:A,1,0) -> Lifeline Multi Ventures Private Limited | F887: true | G887: 2007-11-20T18:30:00.000Z | H887: 2025-11-07T11:27:13.726Z | I887: 2025-11-07T11:27:13.651Z | J887: https://www.infomerics.com/pressrelease/ | K887: lifeline-multi-ventures-private-limited | Q887: 2 | R887: yg0r8xoabi2nh72hqsuefyv6 | S887: Other | T887: true | U887: 2025-04-01T06:06:11.255Z | V887: 2025-04-01T06:06:11.255Z | W887: 2025-04-01T06:06:11.251Z
A888: 5367 | B888: nhqei8vx2x8gmzg4rgypptle | C888: Chadha Papers Limited | D888: =VLOOKUP(C888,'Scraped data '!A:A,1,0) -> Chadha Papers Limited | F888: true | G888: 2008-11-20T18:30:00.000Z | H888: 2025-11-07T11:27:17.156Z | I888: 2025-11-07T11:27:17.081Z | J888: https://www.infomerics.com/pressrelease/ | K888: chadha-papers-limited | Q888: 2 | R888: yg0r8xoabi2nh72hqsuefyv6 | S888: Other | T888: true | U888: 2025-04-01T06:06:11.255Z | V888: 2025-04-01T06:06:11.255Z | W888: 2025-04-01T06:06:11.251Z
A889: 5368 | B889: g9rdfmrlegl54olb33wh22w1 | C889: Shri Bajrang Power & Ispat Limited | D889: =VLOOKUP(C889,'Scraped data '!A:A,1,0) -> Shri Bajrang Power & Ispat Limited | F889: true | G889: 2008-11-20T18:30:00.000Z | H889: 2025-11-07T11:27:20.775Z | I889: 2025-11-07T11:27:20.692Z | J889: https://www.infomerics.com/pressrelease/ | K889: shri-bajrang-power-ispat-limited | Q889: 2 | R889: yg0r8xoabi2nh72hqsuefyv6 | S889: Other | T889: true | U889: 2025-04-01T06:06:11.255Z | V889: 2025-04-01T06:06:11.255Z | W889: 2025-04-01T06:06:11.251Z
A890: 5369 | B890: vn5bm2y0616wf01mzh7t8g3n | C890: Amitex Agro Product Private Limited | D890: =VLOOKUP(C890,'Scraped data '!A:A,1,0) -> Amitex Agro Product Private Limited | F890: true | G890: 2008-11-20T18:30:00.000Z | H890: 2025-11-07T11:27:23.881Z | I890: 2025-11-07T11:27:23.758Z | J890: https://www.infomerics.com/pressrelease/ | K890: amitex-agro-product-private-limited | Q890: 2 | R890: yg0r8xoabi2nh72hqsuefyv6 | S890: Other | T890: true | U890: 2025-04-01T06:06:11.255Z | V890: 2025-04-01T06:06:11.255Z | W890: 2025-04-01T06:06:11.251Z
A891: 5370 | B891: ijzlydol1z3gmqydledt3gw0 | C891: Maa Harsiddhi Infra Developers Private Limited | D891: =VLOOKUP(C891,'Scraped data '!A:A,1,0) -> Maa Harsiddhi Infra Developers Private Limited | F891: true | G891: 2009-11-20T18:30:00.000Z | H891: 2025-11-07T11:27:27.626Z | I891: 2025-11-07T11:27:27.543Z | J891: https://www.infomerics.com/pressrelease/ | K891: maa-harsiddhi-infra-developers-private-limited | Q891: 2 | R891: yg0r8xoabi2nh72hqsuefyv6 | S891: Other | T891: true | U891: 2025-04-01T06:06:11.255Z | V891: 2025-04-01T06:06:11.255Z | W891: 2025-04-01T06:06:11.251Z
A892: 5371 | B892: lknjspyej8kjvob7iiz40z22 | C892: Sindhu Cargo Services Private Limited | D892: =VLOOKUP(C892,'Scraped data '!A:A,1,0) -> Sindhu Cargo Services Private Limited | F892: true | G892: 2009-11-20T18:30:00.000Z | H892: 2025-11-07T11:27:29.841Z | I892: 2025-11-07T11:27:29.770Z | J892: https://www.infomerics.com/pressrelease/ | K892: sindhu-cargo-services-private-limited | Q892: 2 | R892: yg0r8xoabi2nh72hqsuefyv6 | S892: Other | T892: true | U892: 2025-04-01T06:06:11.255Z | V892: 2025-04-01T06:06:11.255Z | W892: 2025-04-01T06:06:11.251Z
A893: 5372 | B893: qzh52cfrklkgaojhw61x6jl3 | C893: Scan Steels Limited | D893: =VLOOKUP(C893,'Scraped data '!A:A,1,0) -> Scan Steels Limited | F893: true | G893: 2009-11-20T18:30:00.000Z | H893: 2025-11-07T11:27:34.866Z | I893: 2025-11-07T11:27:34.695Z | J893: https://www.infomerics.com/pressrelease/ | K893: scan-steels-limited | Q893: 2 | R893: yg0r8xoabi2nh72hqsuefyv6 | S893: Other | T893: true | U893: 2025-04-01T06:06:11.255Z | V893: 2025-04-01T06:06:11.255Z | W893: 2025-04-01T06:06:11.251Z
... A1237: 5717 | B1237: y8jmcne01b5cs262aqgkaxxi | C1237: Bank Of India | D1237: =VLOOKUP(C1237,'Scraped data '!A:A,1,0) -> Bank Of India | F1237: true | G1237: 2021-09-20T20:32:26.000Z | H1237: 2025-11-07T11:43:21.868Z | I1237: 2025-11-07T11:43:21.814Z | J1237: https://www.infomerics.com/pressrelease/ | K1237: bank-of-india | Q1237: 2 | R1237: yg0r8xoabi2nh72hqsuefyv6 | S1237: Other | T1237: true | U1237: 2025-04-01T06:06:11.255Z | V1237: 2025-04-01T06:06:11.255Z | W1237: 2025-04-01T06:06:11.251Z
A1238: 5718 | B1238: tz81x50crakj43nav2gbmm4a | C1238: Babulal Edible Oil Private Limited | D1238: today | F1238: true | G1238: 2021-09-20T21:10:02.000Z | H1238: 2025-11-07T11:43:23.576Z | I1238: 2025-11-07T11:43:23.530Z | J1238: https://www.infomerics.com/pressrelease/ | K1238: babulal-edible-oil-private-limited | Q1238: 2 | R1238: yg0r8xoabi2nh72hqsuefyv6 | S1238: Other | T1238: true | U1238: 2025-04-01T06:06:11.255Z | V1238: 2025-04-01T06:06:11.255Z | W1238: 2025-04-01T06:06:11.251Z
A1239: 5719 | B1239: tl8ubv0sfywp8mjs24ns6bth | C1239: Data Ingenious Global Limited | D1239: =VLOOKUP(C1239,'Scraped data '!A:A,1,0) -> Data Ingenious Global Limited | F1239: true | G1239: 2021-09-20T21:15:37.000Z | H1239: 2025-11-07T11:43:25.293Z | I1239: 2025-11-07T11:43:25.247Z | J1239: https://www.infomerics.com/pressrelease/ | K1239: data-ingenious-global-limited | Q1239: 2 | R1239: yg0r8xoabi2nh72hqsuefyv6 | S1239: Other | T1239: true | U1239: 2025-04-01T06:06:11.255Z | V1239: 2025-04-01T06:06:11.255Z | W1239: 2025-04-01T06:06:11.251Z
A1240: 5720 | B1240: fdzsiec7k7hwix9f4ik5dx3q | C1240: Ritika Vegitables Oil Private Limited | D1240: =VLOOKUP(C1240,'Scraped data '!A:A,1,0) -> #N/A | F1240: true | G1240: 2021-09-20T21:22:14.000Z | H1240: 2025-11-07T11:43:27.019Z | I1240: 2025-11-07T11:43:26.974Z | J1240: https://www.infomerics.com/pressrelease/ | K1240: ritika-vegitables-oil-private-limited | Q1240: 2 | R1240: yg0r8xoabi2nh72hqsuefyv6 | S1240: Other | T1240: true | U1240: 2025-04-01T06:06:11.255Z | V1240: 2025-04-01T06:06:11.255Z | W1240: 2025-04-01T06:06:11.251Z
A1241: 5721 | B1241: cun3fozvntsc1zxfpe73vuj0 | C1241: Shree Hari Agro Industries Limited | D1241: =VLOOKUP(C1241,'Scraped data '!A:A,1,0) -> Shree Hari Agro Industries Limited | F1241: true | G1241: 2021-09-20T21:26:56.000Z | H1241: 2025-11-07T11:43:28.962Z | I1241: 2025-11-07T11:43:28.908Z | J1241: https://www.infomerics.com/pressrelease/ | K1241: shree-hari-agro-industries-limited | Q1241: 2 | R1241: yg0r8xoabi2nh72hqsuefyv6 | S1241: Other | T1241: true | U1241: 2025-04-01T06:06:11.255Z | V1241: 2025-04-01T06:06:11.255Z | W1241: 2025-04-01T06:06:11.251Z
A1242: 5722 | B1242: ra6qasqj7wgjtn7w04pj77q7 | C1242: Vijayneha Polymers Private Limited | D1242: =VLOOKUP(C1242,'Scraped data '!A:A,1,0) -> Vijayneha Polymers Private Limited | F1242: true | G1242: 2021-09-22T07:04:22.000Z | H1242: 2026-01-22T11:49:48.918Z | I1242: 2026-01-22T11:49:48.736Z | J1242: https://www.infomerics.com/pressrelease/ | K1242: vijayneha-polymers-private-limited | Q1242: 2 | R1242: yg0r8xoabi2nh72hqsuefyv6 | S1242: Other | T1242: true | U1242: 2025-04-01T06:06:11.255Z | V1242: 2025-04-01T06:06:11.255Z | W1242: 2025-04-01T06:06:11.251Z
A1243: 5723 | B1243: dmcxfj8hwi2uqokcfa7cmdf6 | C1243: SBL Energy Limited | D1243: =VLOOKUP(C1243,'Scraped data '!A:A,1,0) -> SBL Energy Limited | F1243: true | G1243: 2021-09-21T20:42:25.000Z | H1243: 2025-11-07T11:43:35.488Z | I1243: 2025-11-07T11:43:35.400Z | J1243: https://www.infomerics.com/pressrelease/ | K1243: sbl-energy-limited | Q1243: 2 | R1243: yg0r8xoabi2nh72hqsuefyv6 | S1243: Other | T1243: true | U1243: 2025-04-01T06:06:11.255Z | V1243: 2025-04-01T06:06:11.255Z | W1243: 2025-04-01T06:06:11.251Z
A1244: 5724 | B1244: c7uj8ozza9b774pt90ii1mqf | C1244: Brij Gopal Construction Company Private Limited | D1244: =VLOOKUP(C1244,'Scraped data '!A:A,1,0) -> Brij Gopal Construction Company Private Limited | F1244: true | G1244: 2021-09-21T22:19:01.000Z | H1244: 2025-11-07T11:43:38.514Z | I1244: 2025-11-07T11:43:38.453Z | J1244: https://www.infomerics.com/pressrelease/ | K1244: brij-gopal-construction-company-private-limited | Q1244: 2 | R1244: yg0r8xoabi2nh72hqsuefyv6 | S1244: Other | T1244: true | U1244: 2025-04-01T06:06:11.255Z | V1244: 2025-04-01T06:06:11.255Z | W1244: 2025-04-01T06:06:11.251Z
A1245: 5725 | B1245: waybar8xdxif3zmbjfdp71gp | C1245: Diwakar Enterprises Private Limited | D1245: =VLOOKUP(C1245,'Scraped data '!A:A,1,0) -> Diwakar Enterprises Private Limited | F1245: true | G1245: 2021-09-21T22:28:17.000Z | H1245: 2025-11-07T11:43:40.261Z | I1245: 2025-11-07T11:43:40.221Z | J1245: https://www.infomerics.com/pressrelease/ | K1245: diwakar-enterprises-private-limited | Q1245: 2 | R1245: yg0r8xoabi2nh72hqsuefyv6 | S1245: Other | T1245: true | U1245: 2025-04-01T06:06:11.255Z | V1245: 2025-04-01T06:06:11.255Z | W1245: 2025-04-01T06:06:11.251Z
A1246: 5726 | B1246: vst2axjnkpemwt5rx4uflbf7 | C1246: Chintpurni Steel Private Limited | D1246: =VLOOKUP(C1246,'Scraped data '!A:A,1,0) -> Chintpurni Steel Private Limited | F1246: true | G1246: 2021-09-21T23:45:03.000Z | H1246: 2025-11-07T11:43:42.748Z | I1246: 2025-11-07T11:43:42.685Z | J1246: https://www.infomerics.com/pressrelease/ | K1246: chintpurni-steel-private-limited | Q1246: 2 | R1246: yg0r8xoabi2nh72hqsuefyv6 | S1246: Other | T1246: true | U1246: 2025-04-01T06:06:11.255Z | V1246: 2025-04-01T06:06:11.255Z | W1246: 2025-04-01T06:06:11.251Z
A1247: 5727 | B1247: hp4pinabui1xkk6efvodhnfw | C1247: Narsimha Iron and Steel Private Limited | D1247: =VLOOKUP(C1247,'Scraped data '!A:A,1,0) -> Narsimha Iron and Steel Private Limited | F1247: true | G1247: 2021-09-21T23:48:39.000Z | H1247: 2025-11-07T11:43:45.144Z | I1247: 2025-11-07T11:43:45.088Z | J1247: https://www.infomerics.com/pressrelease/ | K1247: narsimha-iron-and-steel-private-limited | Q1247: 2 | R1247: yg0r8xoabi2nh72hqsuefyv6 | S1247: Other | T1247: true | U1247: 2025-04-01T06:06:11.255Z | V1247: 2025-04-01T06:06:11.255Z | W1247: 2025-04-01T06:06:11.251Z
A1248: 5728 | B1248: bve176ijply4hk3cw8my7pct | C1248: Clifton Export Private Limited | D1248: =VLOOKUP(C1248,'Scraped data '!A:A,1,0) -> Clifton Export Private Limited | F1248: true | G1248: 2021-09-22T23:35:29.000Z | H1248: 2025-11-07T11:43:47.751Z | I1248: 2025-11-07T11:43:47.699Z | J1248: https://www.infomerics.com/pressrelease/ | K1248: clifton-export-private-limited | Q1248: 2 | R1248: yg0r8xoabi2nh72hqsuefyv6 | S1248: Other | T1248: true | U1248: 2025-04-01T06:06:11.255Z | V1248: 2025-04-01T06:06:11.255Z | W1248: 2025-04-01T06:06:11.251Z
...
